Workbook
Name Ass_Vie_Euros_0: Patrimoine!$E$14
Name Ass_Vie_UC_0: Patrimoine!$E$15
Name Assurance: #REF!
Name Assurance: #REF!
Name Autres_Crédits: #REF!
Name Autres_Crédits: #REF!
Name Budget_Théorique: Patrimoine!$O$19
Name Capi_2: #REF!
Name CC_0: Patrimoine!$E$5
Name CEL_0: Patrimoine!$E$9
Name Crédit_Locatif: #REF!
Name Crédit_Locatif: #REF!
Name Crédit_RP: #REF!
Name Crédit_RP: #REF!
Name Crédits_Impôts: #REF!
Name Déduction_Impôts: #REF!
Name Diff_Après_Op: '[1]Calcul Taux d''endettement'!$G$11
Name Diff_Avant_Op: '[1]Calcul Taux d''endettement'!$G$10
Name Durée: #REF!
Name Durée: #REF!
Name Durée_2: '[2]Calculatrice Epargne'!$B$81+1
Name Durée_2: '[3]Calculatrice Epargne'!$B$81+1
Name Epargne_Precaution: Patrimoine!$E$32
Name Impôts_N1: #REF!
Name Int_valo: #REF!
Name Intérêts_2: #REF!
Name LA_0: Patrimoine!$E$6
Name LDD_0: Patrimoine!$E$7
Name LJ_0: Patrimoine!$E$8
Name Loyer: #REF!
Name Loyer: #REF!
Name Loyer_Invest: #REF!
Name Loyer_Invest: #REF!
Name Loyers_Perçus: #REF!
Name Loyers_Perçus: #REF!
Name Menusalité_Invest: #REF!
Name Menusalité_Invest: #REF!
Name Montant_Investir: Patrimoine!$D$35
Name Nb_Part_Fiscale: #REF!
Name Patrimoine_Total: Patrimoine!$H$14
Name PEA_0: Patrimoine!$E$16
Name PEE_0: Patrimoine!$E$17
Name PEL_0: Patrimoine!$E$13
Name PERCO_0: Patrimoine!$E$23
Name PERP_Euros_0: Patrimoine!$E$21
Name PERP_UC_0: Patrimoine!$E$22
Name Réductions_Impôts: #REF!
Name Revenu: #REF!
Name Revenu: #REF!
Name Salaire_N1: #REF!
Name Salaires: #REF!
Name Salaires: #REF!
Name Salires: #REF!
Name Salires: #REF!
Name SCPI_0: Patrimoine!$E$24
Name Taux_crédit: #REF!
Name Taux_crédit: #REF!
Name Temps_2: #REF!
Name Tx_End_Max: #REF!
Name Tx_End_Max: #REF!

Sheet Plan de charge
B2: Vous : | F2: PLAN DE CHARGE / FLUX MENSUEL | N2: Epargne / Stock
B3: Prénom :
B4: Nom : | F4: Revenus | H4: Conjoint | I4: Charges incompressibles (mensuel) | N4: Type de Compte / Placements | O4: Montant | P4: Conjoint | Q4: Global
B5: Date de naissance : | F5: Salaire mensuel net | G5: 0 | H5: 0 | I5: Loyer | J5: 0 | N5: Compte Courant n°1 [0%] : | O5: 0 | P5: 0 | Q5: =SUM(O5:P5) -> 0
B6: Lieu de naissance : | F6: Revenus locatifs | G6: 0 | H6: 0 | I6: Impôt mensuel | J6: 0 | N6: Compte Courant n°2 : | O6: 0 | P6: 0 | Q6: =SUM(O6:P6) -> 0
B7: N°: téléphone: | F7: Revenus mobiliers | G7: 0 | H7: 0 | I7: Impôt foncier | J7: 0 | N7: Compte Courant n°3 : | O7: 0 | P7: 0 | Q7: =SUM(O7:P7) -> 0
B8: Mail: | F8: Revenus BIC | G8: 0 | H8: 0 | I8: Taxe foncière | J8: 0 | N8: Livret A [1,7% net d'IR] max 22 950€ | O8: 0 | P8: 0 | Q8: =SUM(O8:P8) -> 0
B9: Profession: | F9: Revenus BNC | G9: 0 | H9: 0 | I9: Taxe d'habitation | J9: 0 | N9: LDD [1,7% net d'IR] max 12 800€ | O9: 0 | P9: 0 | Q9: =SUM(O9:P9) -> 0
B10: Ancienneté: | F10: Revenus BA | G10: 0 | H10: 0 | I10: Nourriture | J10: 0 | N10: CEL [1% brut soit 0,7% net d'IR] | O10: 0 | P10: 0 | Q10: =SUM(O10:P10) -> 0
B11: Nom de la société: | F11: Pensions | G11: 0 | H11: 0 | I11: Pass Navigo | J11: 0 | N11: Livret Jeune | O11: 0 | P11: 0 | Q11: =SUM(O11:P11) -> 0
F12: Retraite | G12: 0 | H12: 0 | I12: Transport (train, avion) | J12: 0 | N12: PEL [2,5% net d'IR] max 10 000€ | O12: 0 | P12: 0 | Q12: =SUM(O12:P12) -> 0
B13: Conjoint : | F13: Autres | G13: 0 | H13: 0 | I13: Parking | J13: 0 | N13: Compte à terme | O13: 0 | P13: 0 | Q13: =SUM(O13:P13) -> 0
B14: Prénom : | F14: Total | G14: =SUM(G5:G13) -> 0 | H14: =SUM(H5:H13) -> 0 | I14: Electricité | J14: 0 | N14: Epargne court terme | O14: =SUM(O5:O13) -> 0 | P14: =SUM(P5:P13) -> 0 | Q14: =SUM(O14:P14) -> 0
B15: Nom : | I15: Internet | J15: 0 | N15: PEA | O15: 0 | P15: 0 | Q15: =SUM(O15:P15) -> 0
B16: Date de naissance : | I16: Téléphone | J16: 0 | N16: PEE/PEG/PEI | O16: 0 | P16: 0 | Q16: =SUM(O16:P16) -> 0
B17: Lieu de naissance : | I17: Assurance | J17: 0 | N17: Assurance Vie | O17: 0 | P17: 0 | Q17: =SUM(O17:P17) -> 0
B18: Numéro de téléphone : | I18: Crédit résidence principale | J18: 0 | N18: Epargne moyen terme | O18: =SUM(O15:O17) -> 0 | P18: =SUM(P15:P17) -> 0 | Q18: =SUM(O18:P18) -> 0
B19: Mail : | I19: Crédit consomation | J19: 0 | N19: PERCO | O19: 0 | P19: 0 | Q19: =SUM(O19:P19) -> 0
B20: Profession du conjoint: | I20: Pensions alimentaires versées | J20: 0 | N20: PER | O20: 0 | P20: 0 | Q20: =SUM(O20:P20) -> 0
B21: Ancienneté: | I21: Crêches | J21: 0 | N21: SCPI | O21: 0 | P21: 0 | Q21: =SUM(O21:P21) -> 0
B22: Nom de la société: | I22: Autres | J22: 0 | N22: Epargne long terme | O22: =SUM(O19:O21) -> 0 | P22: =SUM(P19:P21) -> 0 | Q22: =SUM(O22:P22) -> 0
I23: Total | J23: =SUM(J5:J22) -> 0 | N23: Autre placement sécurisé | O23: 0 | P23: 0 | Q23: =SUM(O23:P23) -> 0
B24: Adresse actuelle: | N24: Autre placement non sécurisé | O24: 0 | P24: 0 | Q24: =SUM(O24:P24) -> 0
B25: Propriétaire/Locataire: | F25: Budget = Revenus - Charges incompressibles | J25: =SUM(G14:H14)-J23 -> 0 | N25: Prime de départ | O25: 0 | P25: 0 | Q25: =SUM(O25:P25) -> 0
B26: Marié, pacsé etc. : | N26: Autre épargne | O26: =SUM(O23:O25) -> 0 | P26: =SUM(P23:P25) -> 0 | Q26: =SUM(O26:P26) -> 0
B27: Date du mariage/pacs : | N27: Total | O27: =O14+O18+O22+O26 -> 0 | P27: =P14+P18+P22+P26 -> 0 | Q27: =Q14+Q18+Q22+Q26 -> 0
B28: Régime : | F28: Epargne mensuelle actuelle | I28: Loisirs
F29: Livrets | G29: 0 | I29: Restaurants | J29: 0 | N29: Biens Immobiliers
B30: Nombre d'enfant: | F30: PEL | G30: 0 | I30: Sorties | J30: 0
B31: Non | F31: Assurance vie | G31: 0 | I31: Sports | J31: 0 | N31: Type de bien | O31: Montant
B32: Prénom | F32: Investissement locatif | G32: 0 | I32: Vacances | J32: 0 | N32: Résidence principale | O32: 0
B33: Date de naissance | F33: … | G33: 0 | I33: Vêtements, décoration | J33: 0 | N33: Résidence secondaire | O33: 0
F34: … | G34: 0 | I34: Autres - cours divers | J34: 0 | N34: Investissement locatif n°1 | O34: 0
F35: Total pour les projets | G35: =SUM(G29:G34) -> 0 | I35: Total | J35: =SUM(J29:J34) -> 0 | N35: Investissement locatif n°2 | O35: 0
N36: … | O36: 0
F38: Budget Projets théorique | J38: =J25-J35 -> 0 | N38: Crédit (RP/Conso/…) | O38: Crédit 1 | P38: Crédit 2
N39: Mensualités
F40: Budget Projets disponible | J40: =J25-J35-G35 -> 0 | N40: Taux
N41: Capital Restant Dû
F42: Budget Projets désiré | J42: 0 | N42: Date début du crédit
...

Sheet Patrimoine
C2: Situation à l'instant t =0 | H2: Patrimoine Immobilier (en direct) | M2: Flux Mensuels | V2: Proposition Investissement | AA2: Proposition Epargne
D4: Liquidité - Court Terme | I4: Immobilier | N4: Entrant | W4: Arbitrage Epargne de précaution | AB4: Liquidité - Court Terme
D5: CC | E5: =SUM('Plan de charge'!O5:O7) -> 0 | I5: Résidence principale | J5: ='Plan de charge'!O32 -> 0 | N5: Salaire | O5: ='Plan de charge'!G5 -> 0 | W5: CC | X5: =+AC5-E5 -> 1500 | AB5: CC | AC5: 1500
D6: LA | E6: ='Plan de charge'!O8 -> 0 | I6: Investissement locatif | J6: ='Plan de charge'!O34 -> 0 | N6: Revenus locatifs | O6: ='Plan de charge'!G6 -> 0 | W6: CEL | X6: =AC6-E9 -> 0 | AB6: CEL | AC6: 0
D7: LDD | E7: ='Plan de charge'!O9 -> 0 | N7: Autres revenus | O7: =SUM('Plan de charge'!G7:G13) -> 0 | W7: LA | X7: =AC7-E6 -> 28500 | AB7: LA | AC7: =E32-AC5-AC6-AC8-AC9 -> 28500
D8: LJ | E8: ='Plan de charge'!O11 -> 0 | I8: TOTAL IMMOBILIER NET | N8: Total | O8: =SUM(O5:O7) -> 0 | W8: TOTAL | X8: =SUM(X5:X7) -> 30000 | AB8: LDD | AC8: =E7 -> 0
D9: CEL | E9: ='Plan de charge'!O10 -> 0 | I9: =J5+J6-#REF! -> #REF! | AB9: LJ | AC9: =E8 -> 0
D10: TOTAL | E10: =SUM(E5:E9) -> 0 | N10: Sortant | W10: Versements Ponctuels | AB10: TOTAL | AC10: =SUM(AC5:AC9) -> 30000
N11: Loyer | O11: ='Plan de charge'!J5 -> 0 | W11: Assurance Vie (Fds €) | X11: =D35-X12 -> #REF!
D12: Epargne - Moyen Terme | N12: Nourriture | O12: ='Plan de charge'!J10 -> 0 | W12: GIRARDIN | X12: =#REF! -> #REF! | AB12: Epargne - Moyen Terme
D13: PEL | E13: ='Plan de charge'!O12 -> 0 | H13: TOTAL PATRIMOINE | N13: Impôts | O13: =SUM('Plan de charge'!J6:J9) -> 0 | W13: TOTAL | X13: =SUM(X11:X12) -> #REF! | AB13: PEL | AC13: =E13 -> 0
D14: Ass Vie - Fds € | E14: ='Plan de charge'!O20+'Plan de charge'!O23 -> 0 | H14: =I9+D28 -> #REF! | N14: Crédits | O14: ='Plan de charge'!J18+'Plan de charge'!J19 -> 0 | AB14: PEE (monétaire) | AC14: =E14 -> 0
D15: Ass Vie - Fds UC | E15: ='Plan de charge'!O21+'Plan de charge'!O24 -> 0 | N15: Loisirs | O15: ='Plan de charge'!J35 -> 0 | W15: Versements Mensuels | AB15: Assurance Vie (Fds €) | AC15: =X11 -> #REF!
D16: PEA ou PEA / PME | E16: ='Plan de charge'!O16+'Plan de charge'!O15 -> 0 | N16: Autres | O16: ='Plan de charge'!J23-SUM(O11:O14) -> 0 | W16: Assurance Vie | X16: 300 | AB16: TOTAL | AC16: =SUM(AC13:AC15) -> #REF!
D17: PEE | E17: ='Plan de charge'!O17 -> 0 | N17: Total | O17: =SUM(O11:O16) -> 0 | W17: Livret A | X17: =O19-X16 -> -300
D18: TOTAL | E18: =SUM(E13:E17) -> 0 | W18: TOTAL | X18: =X17+X16 -> 0 | AB18: Epargne - Long Terme
N19: Flux Nets | O19: =O8-O17 -> 0 | AB19: PEA ou PEA / PME | AC19: =E16 -> 0
D20: Epargne - Long Terme
D21: PERP - Fds € | E21: ='Plan de charge'!#REF! -> #REF! | AB21: Ass Vie - Fds UC | AC21: =E15 -> 0
D22: PERP - Fds UC | E22: ='Plan de charge'!#REF! -> #REF!
D23: PERCO | E23: ='Plan de charge'!O19 -> 0 | AB23: PEE | AC23: =E17 -> 0
D24: SCPI | E24: ='Plan de charge'!#REF! -> #REF!
D25: TOTAL | E25: =SUM(E21:E24) -> #REF! | AB25: PERCO | AC25: =E23 -> 0
AB26: TOTAL | AC26: =SUM(AC19:AC25) -> 0
D27: TOTAL EPARGNE
D28: =E18+E10+E25 -> #REF!
D31: Epargne de précaution souhaitée
D32: Livret A | E32: 30000
D34: Liquidité - Epargne précaution
D35: =E10-E32 -> -30000
W40: Liquidité - CT | X40: =AC10 -> 30000
W41: PEL - MT | X41: =AC13 -> 0
W42: Ass Vie € - MT | X42: =AC15 -> #REF!
W43: PEE - LT | X43: =AC16 -> #REF!
W44: PERCO - LT | X44: =AC17 -> 0
W45: Ass Vie UC - LT | X45: =AC21 -> 0
W46: PEA - LT | X46: =AC19 -> 0
E68: =150*18 -> 2700
D81: Liquidité - CT | E81: =E10 -> 0 | N81: Court Terme | O81: =SUM('Plan de charge'!O5:O11) -> 0
D82: PEL - MT | E82: =E13 -> 0 | N82: Moyen Terme | O82: =SUM('Plan de charge'!O12:O17,'Plan de charge'!O20:O25,'Plan de charge'!#REF!) -> #REF!
...

Sheet Feuil1
B4: A FAIRE
B6: 1. MAJ onglet plan de charge
B7: 2. MAJ Patrimoine
B8: 3. dupliquer Patrimoine pour SUIVI
B9: 3 . Imprimable

Sheet Solution Patrimoniale
B2: Cahier des charges | E2: Proposition Investissement | J2: Proposition Epargne après Investissement
B3: Patrimoine Financier | C3: =Patrimoine!D28 -> #REF!
B4: Patrimoine Immobilier | C4: =Patrimoine!I9 -> #REF! | F4: Montant à investir | K4: Liquidité - Court Terme | P4: Check Epargne de précaution | Q4: =L10=Epargne_Precaution -> TRUE
B5: Patrimoine Total | C5: =Patrimoine_Total -> #REF! | F5: =Montant_Investir -> -30000 | K5: CC | L5: 1000 | P5: Check Montant à investir | Q5: =G24=Montant_Investir -> FALSE
B6: Epargne de précaution | C6: =Epargne_Precaution -> 30000 | K6: LJ | L6: =G9+Patrimoine!E8 -> 0 | P6: Check Versements Mensuels | Q6: =G31=Budget_Théorique -> TRUE
B7: Montant à optimiser | C7: =Montant_Investir -> -30000 | F7: Arbitrage Epargne de précaution | K7: LA | L7: =G10+Patrimoine!E6 -> 29000 | P7: Check total Patrimoine | Q7: =K31+G23=Patrimoine_Total -> #REF!
B8: Budget mensuel | C8: =Budget_Théorique -> 0 | F8: CC | G8: =L5-CC_0 -> 1000 | K8: LDD | L8: =G11+Patrimoine!E7 -> 0
B9: Profil de risque | C9: Equilibré | F9: LJ | G9: =IF(LJ_0>Epargne_Precaution-'Solution Patrimoniale'!L5,(Epargne_Precaution-'Solution Patrimoniale'!L5)-LJ_0,0) -> 0 | K9: CEL | L9: =G12+Patrimoine!E9 -> 0
F10: LA | G10: =IF(SUM($L$5:L6)<Epargne_Precaution,Epargne_Precaution-SUM($L$5:L6)-LA_0,-LA_0) -> 29000 | K10: TOTAL | L10: =SUM(L5:L9) -> 30000
F11: LDD | G11: =IF(SUM($L$5:L7)<Epargne_Precaution,Epargne_Precaution-SUM($L$5:L7)-LDD_0,-LDD_0) -> 0
F12: CEL | G12: =IF(SUM($L$5:L8)<Epargne_Precaution,Epargne_Precaution-SUM($L$5:L8)-CEL_0,-CEL_0) -> 0 | K12: Epargne - Moyen Terme
F13: TOTAL | G13: =SUM(G8:G12) -> 30000 | K13: PEL | L13: =G16+PEL_0 -> 0
K14: Ass Vie - Fds € | L14: =G17+Ass_Vie_Euros_0 -> 20000
F15: Versements Initiaux | K15: Ass Vie - Fds SCI | L15: =G18 -> 0
F16: PEL | G16: 0 | K16: Ass Vie - Fds UC | L16: =G19+Ass_Vie_UC_0 -> 0
F17: Assurance Vie - Fds € | G17: 20000 | K17: PEA ou PEA / PME | L17: =G20+PEA_0 -> 0
F18: Assurance Vie - Fds SCI | G18: 0 | K18: PEE | L18: =G21+PEE_0 -> 0
F19: Assurance Vie - Fds UC | G19: 0 | K19: TOTAL | L19: =SUM(L13:L18) -> 20000
F20: PEA Novaxia | G20: 0
F21: PEE | G21: 0 | K21: Epargne - Long Terme
F22: SCPI (cash) | G22: 0 | K22: PERP - Fds € | L22: =PERP_Euros_0 -> #REF!
F23: Girardin | G23: 6000 | K23: PERP - Fds UC | L23: =PERP_UC_0 -> #REF!
F24: TOTAL | G24: =SUM(G16:G23) -> 26000 | K24: PERCO | L24: =PERCO_0 -> 0
K25: SCPI | L25: =SCPI_0+G22 -> #REF!
F26: Versements Mensuels | K26: Résidence principale | L26: =Valeur_RP-#REF! -> #REF!
F27: Assurance Vie | G27: 300 | K27: Investissement Locatif | L27: =Valeur_IL-#REF! -> #REF!
F28: PEL | G28: 50 | K28: TOTAL | L28: =SUM(L22:L27) -> #REF!
F29: PINEL / SCPI | G29: 300
F30: Livret A | G30: =Budget_Théorique-SUM(G27:G29) -> -650 | K30: TOTAL PATRIMOINE
F31: TOTAL | G31: =SUM(G27:G30) -> 0 | K31: =L28+L19+L10 -> #REF!
K77: Court Terme | L77: =L10 -> 30000
B78: Liquidité - CT | C78: =L10 -> 30000 | K78: Moyen Terme | L78: =L19 -> 20000
B79: PEL - MT | C79: =L13 -> 0 | K79: Long Terme | L79: =L28 -> #REF!
B80: Ass Vie - MT | C80: =SUM(L14:L16) -> 20000
B81: PEE - MT | C81: =L18 -> 0 | K81: Placements sécurisés | L81: =L10+L13+L14+L22 -> #REF!
B82: PEA - MT | C82: =L17 -> 0 | K82: Placements non sécurisés | L82: =SUM(L15:L18)+L23+L24 -> #REF!
B83: PERP - LT | C83: =L22+L23 -> #REF! | K83: Immobilier | L83: =L26+L27 -> #REF!
B84: PERCO - LT | C84: =L24 -> 0 | K84: SCPI | L84: =+L25 -> #REF!
B85: SCPI - LT | C85: =L25 -> #REF!
B86: Immobilier - LT | C86: =L26+L27 -> #REF!
