Workbook

Sheet MAJ
A1: Date | B1: Modifications
A2: 44369 | B2: Création du fichier (BF)
A3: 44386 | B3: Modif formule TMI (erreur)
A4: 44915 | B4: Modif Tranches d'imposition 2022 + Plafond quotient familial
A5: 44932 | B5: Modif décôte de l'impôt
A6: 44973 | B6: Correction calcul CSG, modif demi-part, modif onglet données
A7: 45013 | B7: Dans l'onglet "Simulateur impôt simplifié 2023" modif Tranches d'imposition 2023 + Plafond quotient familial 2023 / demi-part supplémentaire + Décôte de l'impôt
A8: 45280 | B8: Modif Tranches d'imposition 2024
A9: 45296 | B9: Modif Plafond quotient familial 2024 + décote de l'impôt 2024 + actualisation "simulateur impôt simplifié 2024" avec tableau croisé dynamique
A10: 45726 | B10: Modif Plafond quotient familial 2024 + décote de l'impôt 2024 + actualisation "simulateur impôt simplifié 2024" avec tableau croisé dynamique
A11: 45988 | B11: Modif parent isolé + Enfant élevé seul

Sheet Données
A2: Tranches d'imposition 2025 | F2: Situations particulières | G2: https://www3.impots.gouv.fr/simulateur/calcul_impot/2021/complet/index.htm
A3: 0 | B3: 11600 | C3: 0 | F3: Veuf | G3: http://impotsurlerevenu.org/fonctionnement-de-l-impot/207-part-fiscale-et-garde-alternee.php
A4: =B3 -> 11600 | B4: 29579 | C4: 0.11 | F4: Garde alternée | G4: http://impotsurlerevenu.org/fonctionnement-de-l-impot/210-plafonnement-du-quotient-familial.php
A5: =B4 -> 29579 | B5: 54577 | C5: 0.3 | F5: Parent isolé cases T + N
A6: =B5 -> 54577 | B6: 181917 | C6: 0.41 | F6: Enfant élevé seul case L
A7: =B6 -> 181917 | C7: 0.45 | F7: Titulaire pension invalidité
F8: Titulaire carte du combattant
A9: Situation de famille
A10: Célibataire / Union libre
A11: Mariés / Pacsés
D15: Revenus fonciers
A16: Plafond quotient familial 2025 / demi-part supplémentraire
A17: Plafond demi-part | B17: 1807 | D17: Régime micro-foncier
A18: Plafond 1 part | B18: =B17*2 -> 3614 | D18: Régime réel
A20: Micro-entrepreneur ayant opté pour le versement libératoire de l'impôt et soumis au calcul du taux effectif | F20: Revenus BIC
A21: https://www.corrigetonimpot.fr/taux-effectif-impot-definition-calcul-auto-entrepreneur/ | F21: https://www.lecoindesentrepreneurs.fr/bic-benefices-industriels-et-commerciaux/
F22: http://impotsurlerevenu.org/declarer-ses-revenus/701-l-imposition-des-bic-et-bnc.php
A23: Activité LMNP
F24: Régimes Agricoles (revenus BA)
A25: Régime micro-BIC | F25: https://www.lecoindesentrepreneurs.fr/regime-micro-benefice-agricole/
A26: Régime réel BIC
F27: Retraites, pensions et rentes viagères
F28: https://www.cfdt.fr/portail/outils/special-impot-2021/les-pensions-et-retraites/pensions-retraites-et-rentes-viageres-srv1_1174494
A29: Déduction sur les revenus | B29: https://www.quechoisir.org/actualite-impots-2025-l-indexation-du-bareme-finalement-limitee-a-1-8-n149064/
A30: Minimum actif/personne | B30: 504 | D30: Minimum retraités (/personne) | E30: 450
A31: Maximum actif/personne | B31: 14426 | D31: Maximum retraités (foyer fiscal) | E31: 4399
A33: Décôte de l'impôt | B33: https://www.corrigetonimpot.fr/decote-impot-revenu-calcul-declaration/ | H33: Nbre enfants | I33: Parts fiscales
A34: Imposition des revenus | H34: 0 | I34: 0
A35: Célibataire | B35: 1965 | H35: 1 | I35: 0.5
A36: Couple | B36: 3249 | H36: 2 | I36: 1
A37: La décôte s'obtient par différence entre une somme forfaitaire définie ci-dessous et l'application du taux 45,25% à l'impôt brut | H37: 3 | I37: 2
A38: Somme forfaitaire | H38: 4 | I38: 3
A39: Célibataire | B39: 889 | H39: 5 | I39: 4
A40: Couple | B40: 1470 | H40: 6 | I40: 5
H41: 7 | I41: 6
H42: 8 | I42: 7
A43: CSG / CRDS | B43: 0.172 | H43: 9 | I43: 8
A44: Flat Tax | B44: 0.3 | C44: IR | D44: 0.128 | H44: 10 | I44: 9
A46: Plafond des niches fiscales France Métropole | B46: 10000
A47: Plafond des niches fiscales Outre-Mer | B47: 18000
...

Sheet Simulateur impôt 2025
B1: Simulateur impôt sur le revenu 2025
A3: Consignes : Compléter uniquement les cases blanches ! Ne pas mettre de 0 dans les cases. | H3: Déclarant 1 | I3: Déclarant 2
A4: Situation | B4: Situation familiale | C4: Célibataire / Union libre | F4: Déduction d'IR | G4: Abattement forfaitaire 10% (Traitements & Salaires) | H4: =IF(C9>10*Données!B31,Données!B31,IF(H7<>"","",IF(C9="","",IF(C9>=Données!B31*10,Données!B31,IF(C9<=Données!B30*10,Données!B30,'Simulateur impôt 2025'!C9*0.1))))) | I4: =IF(D9>10*Données!B31,Données!B31,IF(I7<>"","",IF(D9="","",IF(D9>=Données!B31*10,Données!B31,IF(D9<=Données!B30*10,Données!B30,'Simulateur impôt 2025'!D9*0.1))))) | J4: =IF(H4="","",IF('Simulateur impôt 2025'!H4<=Données!B30,"Plancher de 495€ atteint déclarant 1 !",IF('Simulateur impôt 2025'!H4>=Données!B31,"Plafond de 14 171€ atteint déclarant 1 !",""))) | K4: =IF(I4="","",IF('Simulateur impôt 2025'!I4<=Données!B30,"Plancher de 495€ atteint déclarant 2 !",IF('Simulateur impôt 2025'!I4>=Données!B31,"Plafond de 14 171€ atteint déclarant 2 !","")))
B5: Nombre d'enfants à charge | G5: Abattement forfaitaire 10% (Retraites) | H5: =IF(H7<>"","",IF(C10="","",IF(C10>=Données!E31*10,Données!E31,IF(C10<=Données!E30*10,Données!E30,C10*0.1)))) | I5: =IF(I7<>"","",IF(D10="","",IF(D10>=Données!E31*10,Données!E31,IF(D10<=Données!E30*10,Données!E30,D10*0.1)))) | J5: =IF(AND(H5="",I5=""),"",IF(AND(H5="",I5<>""),IF('Simulateur impôt 2025'!I5>=Données!E31,"Plafond de 4 321€ atteint !",IF(AND(I5="",H5<>""),IF('Simulateur impôt 2025'!H5>=Données!E31,"Plafond de 4 321€ atteint !"),"")),IF(AND(I5<>"",H5<>""),IF(I5+H5>=Données!E31,"Plafond de 4 321€ atteint !",""),""))) | K5: =IF(AND(H5="",I5=""),"",IF(AND(I5<=Données!E30,I5<>""),IF(AND(H5<=Données!E30,H5<>""),"Planchers de 442€ atteints pour déclarants 1 & 2","Plancher de 442€ atteint pour déclarant 2"),IF(AND(H5<=Données!E30,H5<>""),"Plancher de 442€ atteint pour déclarant 1","")))
B6: Situations particulières | D6: =IF(C6="","","Simulateur ne prend pas en charge situations particulières") | G6: Abattement forfaitaire 10% (Pensions, rentes) | H6: =IF(C11<>"",C11*0.1,"") | I6: =IF(D11<>"",D11*0.1,"")
B7: Nbre de parts fiscales (sans tenir compte des situations particulières) | C7: =IF(C4="Mariés / Pacsés",VLOOKUP(C5,Données!H34:I44,2,0)+2,VLOOKUP(C5,Données!H34:I44,2,0)+1)+IF(AND(C6=Données!F5,C5>0),0.5,0) -> 1 | G7: Frais réels
C8: Déclarant 1 | D8: =IF(C4="Célibataire / Union libre","","Déclarant 2") | G8: Autres déductions (PER, pension alimentaire, etc)
A9: Revenus | B9: Traitements et salaires | G9: Total des déductions | H9: =SUM(MIN(SUM(H5,I5),Données!E31),H4,I4,H8:I8) -> 0
B10: Retraites
B11: Pensions, rentes viagères | G11: → Revenus net imposables | H11: =SUM(C9:D11,IF(C13=Données!D17,D13*0.7,IF(C13=Données!D18,D13,0)),C15*0.66,C16*0.13,C17:C18,C20:C21,IF(C19=Données!A25,D19*0.5,IF(C19=Données!A26,D19,0)))-H9 -> 0
B12: Revenus des valeurs de capitaux mobiliers (Flat Tax) | D12: =IF(C13="","","Notez les RF ci-dessous en D13") -> Notez les RF ci-dessous en D13
B13: Revenus fonciers (bénéfice ou déficit) | C13: Régime réel | F13: Impôt avant RICI | G13: Impôt sur le revenu avant RICI | H13: =MAX(C31:C32)-IF('Simulateur impôt 2025'!C6=Données!F6,MIN(MAX(C31:C32)-IF(H11/(C7+0.5)<Données!B3,0,IF(H11/(C7+0.5)<Données!B4,(H11/(C7+0.5)-Données!A4)*Données!C4*(C7+0.5),IF(H11/(C7+0.5)<Données!B5,((H11/(C7+0.5)-Données!A5)*Données!C5+(Données!B4-Données!A4)*Données!C4)*(C7+0.5),IF(H11/(C7+0.5)<Données!B6,((H11/(C7+0.5)-Données!A6)*Données!C6+(Données!B5-Données!A5)*Données!C5+(Données!B4-Données!A4)*Données!C4)*(C7+0.5),((H11/(C7+0.5)-Données!A7)*Données!C7+(Données!B6-Données!A6)*Données!C6+(Données!B5-Données!A5)*Données!C5+(Données!B4-Données!A4)*Données!C4)*(C7+0.5))))),1069),0) -> 0 | J13: Tranche 0% | K13: =IF(IF($H$11/C30>Données!B3,Données!B3,Données!A3)<0,0,IF($H$11/C30>Données!B3,Données!B3,$H$11/C30-Données!A3)) -> 0
C14: =IF(C4="Célibataire / Union libre","Déclarant 1","Déclarants 1 & 2") -> Déclarant 1 | G14: Plafond du quotient familial atteint ? | H14: =IF(C32>C31,"Oui","Non") -> Non | I14: =IF(H14="Oui","Plafond quotient familial atteint !","") | J14: Tranche 11% | K14: =IF(IF($H$11/C30>Données!B4,Données!B4,$H$11/C30-Données!A4)<0,0,IF($H$11/C30>Données!B4,Données!B4,$H$11/C30-Données!A4)) -> 0
A15: Revenus professions non salariées | B15: Micro-entrepreneur n'ayant PAS opté pour le versement libératoire de l'impôt | D15: =IF(C15="","","Abattement forfaitaire de 34%") | G15: TMI (Taux Marginal d'Imposition) | H15: =IF(H14="Oui",IF(H11/C30<Données!B3,Données!C3,IF(H11/C30<Données!B4,Données!C4,IF(H11/C30<Données!B5,Données!C5,IF(H11/C30<Données!B6,Données!C6,Données!C7)))),IF(H11/C7<Données!B3,Données!C3,IF(H11/C7<Données!B4,Données!C4,IF(H11/C7<Données!B5,Données!C5,IF(H11/C7<Données!B6,Données!C6,Données!C7))))) -> 0 | J15: Tranche 30% | K15: =IF(IF($H$11/C30>Données!B5,Données!B5,$H$11/C30-Données!A5)<0,0,IF($H$11/C30>Données!B5,Données!B5,$H$11/C30-Données!A5)) -> 0
B16: Revenus agricoles | D16: =IF(C16="","","Abattement forfaitaire de 87%") | J16: Tranche 41% | K16: =IF(IF($H$11/C30>Données!B6,Données!B6,$H$11/C30-Données!A6)<0,0,IF($H$11/C30>Données!B6,Données!B6,$H$11/C30-Données!A6)) -> 0
B17: Revenus industriels et commerciaux professionnels (BIC PRO) | F17: Décôte | G17: =IF(AND(OR(C4=Données!A10,C4=Données!A13,C4=Données!A14),H13<=Données!B35),H30,IF(AND(OR(C4=Données!A11,C4=Données!A12),H13<=Données!B36),H31,0)) -> 889 | J17: Tranche 45% | K17: =IF((H11/C30-Données!A7)<0,0,H11/C30-Données!A7) -> 0
B18: Revenus industriels et commerciaux non professionnels (BIC non PRO) | D18: =IF(C19="","","Notez les BIC ci-dessous en D19") -> Notez les BIC ci-dessous en D19 | I18: Versement FCPI | J18: Pinel
B19: Locations meublées non professionnelles (Revenus BIC, statut LMNP) | C19: Régime micro-BIC | F19: RICI | G19: Réductions d'impôts existantes (RI) | H19: =0.225*I19+J19 -> 0 | I19: 0 | J19: 0
B20: Revenus non commerciaux professionnels (BNC PRO) | G20: Crédits d'impôts existants (CI)
B21: Revenus non commerciaux non professionnels (BNC non PRO) | G21: Total RICI | H21: =SUM(H19:H20) -> 0
F23: Impôt sur le revenu | H23: =IF((H13-G17-H19)<0,0-H20,H13-G17-H21) -> 0
A24: Attention, ce simulateur n'est pas officiel et est à destination exclusive des conseillers en gestion de patrimoine | F24: Impôt provenant de la Flat Tax (12,8%, hors CSG/CRDS) | H24: =C12*Données!D44 -> 0
A25: Si besoin simulateur officiel : https://www3.impots.gouv.fr/simulateur/calcul_impot/2021/complet/index.htm | F25: CSG / CRDS | H25: =(C12+IF(C13="Régime micro-foncier",D13*0.7,D13)+IF(C19="Régime micro-BIC",D19*0.5,D19))*0.172 -> 0
G26: Total | H26: =SUM(H23:H25) -> 0
A30: A masquer | B30: Nombre de parts fiscales (sans compter les enfants pour calcul 2) | C30: =IF(C4="Mariés / Pacsés",2,1) -> 1 | E30: A masquer | G30: Décote célibataire | H30: =Données!B39-('Simulateur impôt 2025'!H13*0.4525) -> 889
A31: A masquer | B31: Calcul 1 (sans prise en compte quotient familial) | C31: =IF(H11/C7<Données!B3,0,IF(H11/C7<Données!B4,(H11/C7-Données!A4)*Données!C4*'Simulateur impôt 2025'!C7,IF(H11/C7<Données!B5,((H11/C7-Données!A5)*Données!C5+(Données!B4-Données!A4)*Données!C4)*'Simulateur impôt 2025'!C7,IF(H11/C7<Données!B6,((H11/C7-Données!A6)*Données!C6+(Données!B5-Données!A5)*Données!C5+(Données!B4-Données!A4)*Données!C4)*'Simulateur impôt 2025'!C7,((H11/C7-Données!A7)*Données!C7+(Données!B6-Données!A6)*Données!C6+(Données!B5-Données!A5)*Données!C5+(Données!B4-Données!A4)*Données!C4)*'Simulateur impôt 2025'!C7)))) -> 0 | E31: A masquer | G31: Décote couple | H31: =Données!B40-('Simulateur impôt 2025'!H13*0.4525) -> 1470
A32: A masquer | B32: Calcul 2 (avec prise en compte quotient familial) | C32: =IF(H11/C30<Données!B3,0,IF(H11/C30<Données!B4,(H11/C30-Données!A4)*Données!C4*'Simulateur impôt 2025'!C30,IF(H11/C30<Données!B5,((H11/C30-Données!A5)*Données!C5+(Données!B4-Données!A4)*Données!C4)*'Simulateur impôt 2025'!C30,IF(H11/C30<Données!B6,((H11/C30-Données!A6)*Données!C6+(Données!B5-Données!A5)*Données!C5+(Données!B4-Données!A4)*Données!C4)*'Simulateur impôt 2025'!C30,((H11/C30-Données!A7)*Données!C7+(Données!B6-Données!A6)*Données!C6+(Données!B5-Données!A5)*Données!C5+(Données!B4-Données!A4)*Données!C4)*'Simulateur impôt 2025'!C30))))-(C7-C30)*Données!B18 -> 0

Sheet Simulateur impôt simplifié 2025
A1: Simulateur impôt sur le revenu 2025
A3: Consignes : compléter les 6 cases blanches
A4: Situation familiale | B4: Mariés / Pacsés | D4: Impôt avant RICI | E4: Impôt sur le revenu avant RICI | F4: =MAX(B17:B18) -> 2046 | I4: Tranches d'imposition 2025
A5: Nombre d'enfants à charge | B5: 2 | E5: Plafond du quotient familial atteint ? | F5: =IF(B18>B17,"Oui","Non") -> Non | G5: =IF(F5="Oui","Plafond quotient familial atteint !","") | I5: =Données!A3 -> 0 | J5: =Données!B3 -> 11600 | K5: 0
A6: Nbre de parts fiscales | B6: =IF(B4="Mariés / Pacsés",VLOOKUP(B5,I40:J50,2,0)+2,VLOOKUP(B5,I40:J50,2,0)+1) -> 3 | E6: TMI (Taux Marginal d'Imposition) | F6: =IF(F5="Oui",IF(B7/B16<'Simulateur impôt simplifié 2025'!J5,'Simulateur impôt simplifié 2025'!K5,IF(B7/B16<'Simulateur impôt simplifié 2025'!J6,'Simulateur impôt simplifié 2025'!K6,IF(B7/B16<'Simulateur impôt simplifié 2025'!J7,'Simulateur impôt simplifié 2025'!K7,IF(B7/B16<'Simulateur impôt simplifié 2025'!J8,'Simulateur impôt simplifié 2025'!K8,'Simulateur impôt simplifié 2025'!K9)))),IF(B7/B6<'Simulateur impôt simplifié 2025'!J5,'Simulateur impôt simplifié 2025'!K5,IF(B7/B6<'Simulateur impôt simplifié 2025'!J6,'Simulateur impôt simplifié 2025'!K6,IF(B7/B6<'Simulateur impôt simplifié 2025'!J7,'Simulateur impôt simplifié 2025'!K7,IF(B7/B6<'Simulateur impôt simplifié 2025'!J8,'Simulateur impôt simplifié 2025'!K8,'Simulateur impôt simplifié 2025'!K9))))) -> 0.11 | I6: =Données!A4 -> 11600 | J6: =Données!B4 -> 29579 | K6: 0.11
A7: Revenus nets imposables (après abattement) | B7: 53400 | I7: =Données!A5 -> 29579 | J7: =Données!B5 -> 54577 | K7: 0.3
D8: Décôte | E8: =IF(AND(OR(B4='Simulateur impôt simplifié 2025'!I13,B4='Simulateur impôt simplifié 2025'!I16,B4='Simulateur impôt simplifié 2025'!I17),F4<='Simulateur impôt simplifié 2025'!J31),F16,IF(AND(OR(B4='Simulateur impôt simplifié 2025'!I14,B4='Simulateur impôt simplifié 2025'!I15),F4<='Simulateur impôt simplifié 2025'!J32),F17,0)) -> 544.185 | I8: =Données!A6 -> 54577 | J8: =Données!B6 -> 181917 | K8: 0.41
I9: =Données!A7 -> 181917 | K9: 0.45
D10: RICI | E10: Réductions d'impôts existantes (RI)
E11: Crédits d'impôts existants (CI)
E12: Total RICI | F12: =SUM(F10:F11) -> 0 | I12: Situation de famille
I13: Célibataire / Union libre
D14: Impôt sur le revenu | F14: =IF((F4-E8-F10)<0,0-F11,F4-E8-F12) -> 1501.815 | I14: Mariés / Pacsés
A16: Nombre de parts fiscales (sans compter les enfants pour calcul 2) | B16: =IF(B4="Mariés / Pacsés",2,1) -> 2 | E16: Décote célibataire | F16: ='Simulateur impôt simplifié 2025'!J35-('Simulateur impôt simplifié 2025'!F4*0.4525) -> -36.815
A17: Calcul 1 (sans prise en compte quotient familial) | B17: =IF(B7/B6<'Simulateur impôt simplifié 2025'!J5,0,IF(B7/B6<'Simulateur impôt simplifié 2025'!J6,(B7/B6-'Simulateur impôt simplifié 2025'!I6)*'Simulateur impôt simplifié 2025'!K6*'Simulateur impôt simplifié 2025'!B6,IF(B7/B6<'Simulateur impôt simplifié 2025'!J7,((B7/B6-'Simulateur impôt simplifié 2025'!I7)*'Simulateur impôt simplifié 2025'!K7+('Simulateur impôt simplifié 2025'!J6-'Simulateur impôt simplifié 2025'!I6)*'Simulateur impôt simplifié 2025'!K6)*'Simulateur impôt simplifié 2025'!B6,IF(B7/B6<'Simulateur impôt simplifié 2025'!J8,((B7/B6-'Simulateur impôt simplifié 2025'!I8)*'Simulateur impôt simplifié 2025'!K8+('Simulateur impôt simplifié 2025'!J7-'Simulateur impôt simplifié 2025'!I7)*'Simulateur impôt simplifié 2025'!K7+('Simulateur impôt simplifié 2025'!J6-'Simulateur impôt simplifié 2025'!I6)*'Simulateur impôt simplifié 2025'!K6)*'Simulateur impôt simplifié 2025'!B6,((B7/B6-'Simulateur impôt simplifié 2025'!I9)*'Simulateur impôt simplifié 2025'!K9+('Simulateur impôt simplifié 2025'!J8-'Simulateur impôt simplifié 2025'!I8)*'Simulateur impôt simplifié 2025'!K8+('Simulateur impôt simplifié 2025'!J7-'Simulateur impôt simplifié 2025'!I7)*'Simulateur impôt simplifié 2025'!K7+('Simulateur impôt simplifié 2025'!J6-'Simulateur impôt simplifié 2025'!I6)*'Simulateur impôt simplifié 2025'!K6)*'Simulateur impôt simplifié 2025'!B6)))) -> 2046 | E17: Décote couple | F17: ='Simulateur impôt simplifié 2025'!J36-('Simulateur impôt simplifié 2025'!F4*0.4525) -> 544.185
A18: Calcul 2 (avec prise en compte quotient familial) | B18: =IF(B7/B16<'Simulateur impôt simplifié 2025'!J5,0,IF(B7/B16<'Simulateur impôt simplifié 2025'!J6,(B7/B16-'Simulateur impôt simplifié 2025'!I6)*'Simulateur impôt simplifié 2025'!K6*'Simulateur impôt simplifié 2025'!B16,IF(B7/B16<'Simulateur impôt simplifié 2025'!J7,((B7/B16-'Simulateur impôt simplifié 2025'!I7)*'Simulateur impôt simplifié 2025'!K7+('Simulateur impôt simplifié 2025'!J6-'Simulateur impôt simplifié 2025'!I6)*'Simulateur impôt simplifié 2025'!K6)*'Simulateur impôt simplifié 2025'!B16,IF(B7/B16<'Simulateur impôt simplifié 2025'!J8,((B7/B16-'Simulateur impôt simplifié 2025'!I8)*'Simulateur impôt simplifié 2025'!K8+('Simulateur impôt simplifié 2025'!J7-'Simulateur impôt simplifié 2025'!I7)*'Simulateur impôt simplifié 2025'!K7+('Simulateur impôt simplifié 2025'!J6-'Simulateur impôt simplifié 2025'!I6)*'Simulateur impôt simplifié 2025'!K6)*'Simulateur impôt simplifié 2025'!B16,((B7/B16-'Simulateur impôt simplifié 2025'!I9)*'Simulateur impôt simplifié 2025'!K9+('Simulateur impôt simplifié 2025'!J8-'Simulateur impôt simplifié 2025'!I8)*'Simulateur impôt simplifié 2025'!K8+('Simulateur impôt simplifié 2025'!J7-'Simulateur impôt simplifié 2025'!I7)*'Simulateur impôt simplifié 2025'!K7+('Simulateur impôt simplifié 2025'!J6-'Simulateur impôt simplifié 2025'!I6)*'Simulateur impôt simplifié 2025'!K6)*'Simulateur impôt simplifié 2025'!B16))))-(B6-B16)*'Simulateur impôt simplifié 2025'!J22 -> -292
I20: Plafond quotient familial 2025 / demi-part supplémentraire
I21: Plafond demi-part | J21: =Données!B17 -> 1807
I22: Plafond 1 part | J22: =Données!B18 -> 3614
I25: Déduction sur les revenus | J25: https://www.quechoisir.org/actualite-bareme-progressif-de-l-impot-4-8-en-2024-n111386/
I26: Minimum actif/personne | J26: =Données!B30 -> 504 | L26: Minimum retraités (/personne) | M26: =Données!E30 -> 450
I27: Maximum actif/personne | J27: =Données!B31 -> 14426 | L27: Maximum retraités (foyer fiscal) | M27: =Données!E31 -> 4399
I29: Décôte de l'impôt
I30: Imposition des revenus
I31: Célibataire | J31: =Données!B35 -> 1965
I32: Couple | J32: =Données!B36 -> 3249
I33: La décôte s'obtient par différence entre une somme forfaitaire définie ci-dessous et l'application du taux 45,25% à l'impôt brut
I34: Somme forfaitaire
I35: Célibataire | J35: =Données!B39 -> 889
I36: Couple | J36: =Données!B40 -> 1470
I39: Nbre enfants | J39: Parts fiscales
I40: 0 | J40: 0
I41: 1 | J41: 0.5
I42: 2 | J42: 1
I43: 3 | J43: 2
I44: 4 | J44: 3
I45: 5 | J45: 4
I46: 6 | J46: 5
I47: 7 | J47: 6
I48: 8 | J48: 7
...
